#Expyriment 0.9.0 (Python 2.7.12), .xpe-file, coding: UTF-8
#date: Mon Apr 03 2017 16:10:58
#sha1: cd3963
#modules: config.py (b6b1b3)
#display: size=(1024, 768), window_mode=True, open_gl=2
#os: ('Linux', 'borear-desktop', '3.13.0-24-generic', '#47-Ubuntu SMP Fri May 2 23:30:00 UTC 2014', 'x86_64', 'x86_64')
Time,Type,Event,Value,Detail,Detail2
5829,Stimulus,presented,0
11010,design,log,
#design: #exp: test
#design: block_cnt,block_id,trial_cnt,trial_id
11010,design,logged,
11010,Experiment,started
11012,Stimulus,presented,2
13526,Stimulus,presented,1
13528,stderr,received,'Traceback (most recent call last):'
13528,stderr,received,'  File "ld_test.py", line 61, in <module>'
13528,stderr,received,'    startBlock = datetime.now()'
13528,stderr,received,"NameError: name 'datetime' is not defined"
